Workbook

Sheet War_Reg_Season_Pivot
A3: Sum of war_reg_season | B3: Column Labels
A4: Row Labels | B4: 2014 | C4: 2015 | D4: 2016 | E4: 2017 | F4: 2018 | G4: 2019 | H4: 2020 | I4: Grand Total | K4: Row Labels | L4: 2014 | M4: 2015 | N4: 2016 | O4: 2017 | P4: 2018 | Q4: 2019 | R4: 2020 | S4: Grand Total
A5: DET | B5: 17.97224 | C5: 23.720107 | D5: 28.620367 | E5: 23.168568 | F5: 27.042912 | G5: 26.371181 | H5: 13.560326 | I5: 160.4557 | K5: DET | L5: 17.97224 | M5: 23.720107 | N5: 28.620367 | O5: 23.168568 | P5: 27.042912 | Q5: 26.371181 | R5: 13.560326 | S5: 160.4557
A6: PHI | B6: 1.3364467 | C6: 4.446727 | D6: 2.6394647 | E6: 13.787206 | F6: 40.623144 | G6: 34.388295 | H6: 27.340919 | I6: 124.5622 | K6: PHI | L6: 1.3364467 | M6: 4.446727 | N6: 2.6394647 | O6: 13.787206 | P6: 40.623144 | Q6: 34.388295 | R6: 27.340919 | S6: 124.5622
A7: Grand Total | B7: 19.308687 | C7: 28.166834 | D7: 31.259831 | E7: 36.955775 | F7: 67.666055 | G7: 60.759477 | H7: 40.901245 | I7: 285.0179
L40: =(M5-L5)/M5 -> 0.24232046 | M40: =(N5-M5)/N5 -> 0.17121581 | N40: =(O5-N5)/O5 -> -0.23531011 | O40: =(P5-O5)/P5 -> 0.1432665 | P40: =(Q5-P5)/Q5 -> -0.025472134 | Q40: =(R5-Q5)/R5 -> -0.94473066
L41: =(M6-L6)/M6 -> 0.69945384 | M41: =(N6-M6)/N6 -> -0.6847079 | N41: =(O6-N6)/O6 -> 0.80855696 | O41: =(P6-O6)/P6 -> 0.6606071 | P41: =(Q6-P6)/Q6 -> -0.18130728 | Q41: =(R6-Q6)/R6 -> -0.25775929

Sheet basketball_stats
A1: player_name | B1: player_id | C1: season | D1: season_type | E1: team | F1: poss | G1: mp | H1: raptor_box_offense | I1: raptor_box_defense | J1: raptor_box_total | K1: raptor_onoff_offense | L1: raptor_onoff_defense | M1: raptor_onoff_total | N1: raptor_offense | O1: raptor_defense | P1: raptor_total | Q1: war_total | R1: war_reg_season | S1: war_playoffs | T1: predator_offense | U1: predator_defense | V1: predator_total | W1: pace_impact
A2: Alex Abrines | B2: abrinal01 | C2: 2017 | D2: PO | E2: OKC | F2: 172 | G2: 80 | H2: 0.42082811 | I2: -2.8624539 | J2: -2.4416258 | K2: -6.1838244 | L2: -19.474686 | M2: -25.65851 | N2: -0.89261698 | O2: -6.5612583 | P2: -7.4538753 | Q2: -0.19870044 | R2: 0 | S2: -0.19870044 | T2: -3.2981783 | U2: -6.5351134 | V2: -9.8332918 | W2: 0.3346782
A3: Alex Abrines | B3: abrinal01 | C3: 2017 | D3: RS | E3: OKC | F3: 2215 | G3: 1055 | H3: 0.77071696 | I3: -0.179621 | J3: 0.59109596 | K3: 0.02913419 | L3: -2.6442617 | M3: -2.6151275 | N3: 0.654933 | O3: -0.72423344 | P3: -0.06930043 | Q3: 1.4477081 | R3: 1.4477081 | S3: 0 | T3: 0.33920053 | U3: -0.61186597 | V3: -0.27266544 | W3: 0.32577083
A4: Alex Abrines | B4: abrinal01 | C4: 2018 | D4: PO | E4: OKC | F4: 233 | G4: 110 | H4: 1.123761 | I4: -1.8074857 | J4: -0.68372467 | K4: 4.965907 | L4: 10.916521 | M4: 15.882428 | N4: 1.8751573 | O4: 0.74029234 | P4: 2.6154497 | Q4: 0.31139231 | R4: 0 | S4: 0.31139231 | T4: 2.8775194 | U4: -0.52095356 | V4: 2.3565658 | W4: 0.26047931
A5: Alex Abrines | B5: abrinal01 | C5: 2018 | D5: RS | E5: OKC | F5: 2313 | G5: 1134 | H5: 0.23633529 | I5: -1.7170488 | J5: -1.4807135 | K5: -1.9220898 | L5: -1.154375 | M5: -3.0764647 | N5: -0.2118177 | O5: -1.7285836 | P5: -1.9404013 | Q5: 0.46591215 | R5: 0.46591215 | S5: 0 | T5: -0.48207847 | U5: -1.1722274 | V5: -1.6543059 | W5: -0.5283299
A6: Alex Abrines | B6: abrinal01 | C6: 2019 | D6: RS | E6: OKC | F6: 1279 | G6: 588 | H6: -3.2156832 | I6: 1.0783985 | J6: -2.1372847 | K6: -6.1588565 | L6: 4.9011683 | M6: -1.2576882 | N6: -4.0401566 | O6: 1.8856184 | P6: -2.1545382 | Q6: 0.17816732 | R6: 0.17816732 | S6: 0 | T6: -4.5776776 | U6: 1.5432817 | V6: -3.0343959 | W6: -0.2680131
A7: Quincy Acy | B7: acyqu01 | C7: 2014 | D7: RS | E7: TOR | F7: 125 | G7: 61 | H7: -0.79299467 | I7: 1.2638272 | J7: 0.47083248 | K7: 0.53899943 | L7: -8.7046987 | M7: -8.1656993 | N7: -0.60342327 | O7: -0.7757623 | P7: -1.3791856 | Q7: 0.042632549 | R7: 0.042632549 | S7: 0 | T7: 1.1164118 | U7: 0.36725336 | V7: 1.4836652 | W7: -0.067921363
A8: Quincy Acy | B8: acyqu01 | C8: 2014 | D8: RS | E8: SAC | F8: 1591 | G8: 786 | H8: -1.7886031 | I8: 0.04427844 | J8: -1.7443246 | K8: -0.39267768 | L8: -1.1081323 | M8: -1.50081 | N8: -1.6408255 | O8: -0.17253544 | P8: -1.8133609 | Q8: 0.37328553 | R8: 0.37328553 | S8: 0 | T8: -1.6671849 | U8: -0.27018796 | V8: -1.9373728 | W8: -0.59315792
A9: Quincy Acy | B9: acyqu01 | C9: 2015 | D9: RS | E9: NYK | F9: 2517 | G9: 1287 | H9: -2.0149564 | I9: -1.2684399 | J9: -3.2833963 | K9: -3.8552074 | L9: 2.8038416 | M9: -1.0513659 | N9: -2.4560646 | O9: -0.42094805 | P9: -2.8770126 | Q9: -0.083312615 | R9: -0.083312615 | S9: 0 | T9: -2.797224 | U9: -1.6480242 | V9: -4.4452482 | W9: -0.1004535
A10: Quincy Acy | B10: acyqu01 | C10: 2016 | D10: RS | E10: SAC | F10: 1852 | G10: 876 | H10: -0.008327617 | I10: 0.34078337 | J10: 0.33245575 | K10: -2.7984897 | L10: 0.1303009 | M10: -2.6681888 | N10: -0.58754047 | O10: 0.35393338 | P10: -0.23360709 | Q10: 1.1234791 | R10: 1.1234791 | S10: 0 | T10: -1.4061077 | U10: 0.021970053 | V10: -1.3841377 | W10: -0.10298834
A11: Quincy Acy | B11: acyqu01 | C11: 2017 | D11: RS | E11: DAL | F11: 94 | G11: 48 | H11: -5.4008961 | I11: -1.0349862 | J11: -6.4358822 | K11: -8.1644271 | L11: -3.5896474 | M11: -11.754075 | N11: -6.2285844 | O11: -1.6131581 | P11: -7.8417425 | Q11: -0.12515553 | R11: -0.12515553 | S11: 0 | T11: -4.2973704 | U11: -1.8473044 | V11: -6.1446748 | W11: 0.36248295
A12: Quincy Acy | B12: acyqu01 | C12: 2017 | D12: RS | E12: BRK | F12: 1075 | G12: 510 | H12: 0.3319824 | I12: 0.57369359 | J12: 0.90567599 | K12: -0.74898729 | L12: 1.1911258 | M12: 0.44213847 | N12: 0.170961 | O12: 0.76758706 | P12: 0.93854806 | Q12: 0.96078755 | R12: 0.96078755 | S12: 0 | T12: -0.62694646 | U12: 0.097180198 | V12: -0.52976626 | W12: 0.10424323
A13: Quincy Acy | B13: acyqu01 | C13: 2018 | D13: RS | E13: BRK | F13: 2856 | G13: 1359 | H13: -2.6200316 | I13: -0.8062691 | J13: -3.4263007 | K13: 0.055169946 | L13: -0.01919541 | M13: 0.035974536 | N13: -2.2081824 | O13: -0.65881419 | P13: -2.8669966 | Q13: -0.08123232 | R13: -0.08123232 | S13: 0 | T13: -1.8268132 | U13: -0.89024624 | V13: -2.7170594 | W13: 0.13613926
... A5084: Raul Neto | B5084: netora01 | C5084: 2020 | D5084: RS | E5084: PHI | F5084: 1193 | G5084: 565 | H5084: -0.96206907 | I5084: 3.5245651 | J5084: 2.5624961 | K5084: -4.9653394 | L5084: 3.3305757 | M5084: -1.6347636 | N5084: -1.8651186 | O5084: 3.6571546 | P5084: 1.7920359 | Q5084: 1.3068849 | R5084: 1.3068849 | S5084: 0 | T5084: -1.6317519 | U5084: 2.7071106 | V5084: 1.0753586 | W5084: -0.18816763
A5085: Malik Newman | B5085: newmama01 | C5085: 2020 | D5085: RS | E5085: CLE | F5085: 8 | G5085: 4 | N5085: 0 | O5085: 0 | P5085: 0 | S5085: 0 | T5085: 0 | U5085: 0 | V5085: 0
A5086: Georges Niang | B5086: niangge01 | C5086: 2020 | D5086: RS | E5086: UTA | F5086: 1642 | G5086: 772 | H5086: 1.1918373 | I5086: -2.1541043 | J5086: -0.96226706 | K5086: -1.7104035 | L5086: -1.9412451 | M5086: -3.6516486 | N5086: 0.64833848 | O5086: -2.2609015 | P5086: -1.612563 | Q5086: 0.44676643 | R5086: 0.44676643 | S5086: 0 | T5086: -0.042572858 | U5086: -2.879436 | V5086: -2.9220088 | W5086: -0.28244427
A5087: Nerlens Noel | B5087: noelne01 | C5087: 2020 | D5087: RS | E5087: OKC | F5087: 2110 | G5087: 1014 | H5087: -0.66304738 | I5087: 2.7056938 | J5087: 2.0426464 | K5087: -3.0813743 | L5087: 1.2056909 | M5087: -1.8756834 | N5087: -1.2179571 | O5087: 2.5988071 | P5087: 1.38085 | Q5087: 2.129607 | R5087: 2.129607 | S5087: 0 | T5087: -0.96769591 | U5087: 3.9866759 | V5087: 3.01898 | W5087: -0.35589369
A5088: Zach Norvell Jr. | B5088: norveza01 | C5088: 2020 | D5088: RS | E5088: GSW | F5088: 80 | G5088: 36 | H5088: -3.0034546 | I5088: -3.5955413 | J5088: -6.5989959 | K5088: 4.3506951 | L5088: -17.031947 | M5088: -12.681252 | N5088: -1.5807868 | O5088: -6.5711803 | P5088: -8.1519671 | Q5088: -0.10146445 | R5088: -0.10146445 | S5088: 0 | T5088: -0.048718524 | U5088: -4.6462891 | V5088: -4.6950076 | W5088: 2.3077533
A5089: Zach Norvell Jr. | B5089: norveza01 | C5089: 2020 | D5089: RS | E5089: LAL | F5089: 12 | G5089: 5 | H5089: -10.92871 | I5089: -9.0556304 | J5089: -19.984341 | K5089: -9.0909774 | L5089: -7.8500111 | M5089: -16.940988 | N5089: -11.271088 | O5089: -9.3962668 | P5089: -20.667355 | Q5089: -0.045218038 | R5089: -0.045218038 | S5089: 0 | T5089: -9.4927527 | U5089: -10.213794 | V5089: -19.706546 | W5089: -1.0912605
A5090: Jaylen Nowell | B5090: nowelja01 | C5090: 2020 | D5090: RS | E5090: MIN | F5090: 338 | G5090: 151 | H5090: -1.3957533 | I5090: 0.21792646 | J5090: -1.1778268 | K5090: -5.2631524 | L5090: 6.8915509 | M5090: 1.6283985 | N5090: -2.2527667 | O5090: 1.6552305 | P5090: -0.59753622 | Q5090: 0.16616122 | R5090: 0.16616122 | S5090: 0 | T5090: -2.4546708 | U5090: -0.63211811 | V5090: -3.0867889 | W5090: 0.20598938
A5091: Frank Ntilikina | B5091: ntilila01 | C5091: 2020 | D5091: RS | E5091: NYK | F5091: 2461 | G5091: 1187 | H5091: -2.4695866 | I5091: -0.035065769 | J5091: -2.5046524 | K5091: -1.4114772 | L5091: 0.55971725 | M5091: -0.85175995 | N5091: -2.348935 | O5091: 0.12330997 | P5091: -2.225625 | Q5091: 0.31567848 | R5091: 0.31567848 | S5091: 0 | T5091: -2.7001632 | U5091: 0.78917677 | V5091: -1.9109864 | W5091: -0.60589125
A5092: Kendrick Nunn | B5092: nunnke01 | C5092: 2020 | D5092: RS | E5092: MIA | F5092: 3802 | G5092: 1846 | H5092: 0.53816579 | I5092: -0.41137186 | J5092: 0.12679393 | K5092: 0.36109567 | L5092: -1.6434954 | M5092: -1.2823997 | N5092: 0.49819304 | O5092: -0.70540606 | P5092: -0.20721302 | Q5092: 2.3906104 | R5092: 2.3906104 | S5092: 0 | T5092: 0.14493163 | U5092: -0.7955125 | V5092: -0.65058087 | W5092: -0.1814153
A5093: David Nwaba | B5093: nwabada01 | C5093: 2020 | D5093: RS | E5093: BRK | F5093: 585 | G5093: 268 | H5093: -0.58322534 | I5093: 5.8448231 | J5093: 5.2615978 | K5093: -2.8804581 | L5093: 9.2680316 | M5093: 6.3875735 | N5093: -1.0939168 | O5093: 6.899714 | P5093: 5.8057972 | Q5093: 1.174901 | R5093: 1.174901 | S5093: 0 | T5093: -1.8341883 | U5093: 4.5732122 | V5093: 2.7390239 | W5093: 0.43897443
A5094: Semi Ojeleye | B5094: ojelese01 | C5094: 2020 | D5094: RS | E5094: BOS | F5094: 1861 | G5094: 891 | H5094: -1.4046713 | I5094: 1.7383524 | J5094: 0.33368109 | K5094: -4.2718781 | L5094: -0.05018335 | M5094: -4.3220615 | N5094: -2.140423 | O5094: 1.4184911 | P5094: -0.72193191 | Q5094: 0.91471367 | R5094: 0.91471367 | S5094: 0 | T5094: -2.4075481 | U5094: 0.53354346 | V5094: -1.8740046 | W5094: -0.79882213
A5095: Jahlil Okafor | B5095: okafoja01 | C5095: 2020 | D5095: RS | E5095: NOP | F5095: 916 | G5095: 424 | H5095: -1.2412911 | I5095: -1.0274218 | J5095: -2.2687129 | K5095: -1.7300098 | L5095: -6.7305615 | M5095: -8.4605712 | N5095: -1.4306407 | O5095: -2.2546497 | P5095: -3.6852904 | Q5095: -0.20144716 | R5095: -0.20144716 | S5095: 0 | T5095: -1.2112329 | U5095: -1.20832 | V5095: -2.4195529 | W5095: -0.44319433
A5096: Elie Okobo | B5096: okoboel01 | C5096: 2020 | D5096: RS | E5096: PHO | F5096: 1489 | G5096: 707 | H5096: -1.3369143 | I5096: -3.1818605 | J5096: -4.5187748 | K5096: -2.5101492 | L5096: -0.69659163 | M5096: -3.2067408 | N5096: -1.6698796 | O5096: -2.8365825 | P5096: -4.5064621 | Q5096: -0.62511341 | R5096: -0.62511341 | S5096: 0 | T5096: -1.9878785 | U5096: -2.7319129 | V5096: -4.7197914 | W5096: -1.3620216
A5097: Josh Okogie | B5097: okogijo01 | C5097: 2020 | D5097: RS | E5097: MIN | F5097: 3412 | G5097: 1547 | H5097: -2.032874 | I5097: 0.36883982 | J5097: -1.6640342 | K5097: -1.9352343 | L5097: 0.34429648 | M5097: -1.5909378 | N5097: -2.1202983 | O5097: 0.40696893 | P5097: -1.7133294 | Q5097: 0.82553467 | R5097: 0.82553467 | S5097: 0 | T5097: -2.4858062 | U5097: 0.81366302 | V5097: -1.6721432 | W5097: 0.91125971
... A5255: Ivica Zubac | B5255: zubaciv01 | C5255: 2020 | D5255: RS | E5255: LAC | F5255: 2441 | G5255: 1156 | H5255: 0.91517952 | I5255: 3.7132328 | J5255: 4.6284123 | K5255: 0.90254413 | L5255: 2.0028825 | M5255: 2.9054267 | N5255: 0.92712938 | O5255: 3.4778418 | P5255: 4.4049712 | Q5255: 4.2035852 | R5255: 4.2035852 | S5255: 0 | T5255: -0.19872492 | U5255: 3.0660347 | V5255: 2.8673097 | W5255: -0.39518247

Sheet RS_2020
A1: player_name | B1: player_id | C1: season | D1: season_type | E1: team | F1: poss | G1: mp | H1: raptor_box_offense | I1: raptor_box_defense | J1: raptor_box_total | K1: raptor_onoff_offense | L1: raptor_onoff_defense | M1: raptor_onoff_total | N1: raptor_offense | O1: raptor_defense | P1: raptor_total | Q1: war_total | R1: war_reg_season | S1: war_playoffs | T1: predator_offense | U1: predator_defense | V1: predator_total | W1: pace_impact
A2: Aaron Gordon | B2: gordoaa01 | C2: 2020 | D2: RS | E2: ORL | F2: 3971 | G2: 1914 | H2: -0.44520868 | I2: -0.88143689 | J2: -1.3266456 | K2: 2.4795223 | L2: -3.0172003 | M2: -0.537678 | N2: 0.16868111 | O2: -1.4155028 | P2: -1.2468217 | Q2: 1.4600007 | R2: 1.4600007 | S2: 0 | T2: 0.45989103 | U2: -0.94282868 | V2: -0.48293765 | W2: -0.54791212
A3: Aaron Holiday | B3: holidaa01 | C3: 2020 | D3: RS | E3: IND | F3: 2853 | G3: 1368 | H3: -0.13257179 | I3: 1.5597156 | J3: 1.4271438 | K3: 3.0063983 | L3: -1.0597074 | M3: 1.9466909 | N3: 0.51212541 | O3: 1.0771858 | P3: 1.5893112 | Q3: 3.0206452 | R3: 3.0206452 | S3: 0 | T3: 0.4036352 | U3: 1.0512733 | V3: 1.4549085 | W3: -0.26910778
A4: Abdel Nader | B4: naderab01 | C4: 2020 | D4: RS | E4: OKC | F4: 1603 | G4: 756 | H4: -2.55239 | I4: 0.61266339 | J4: -1.9397266 | K4: -6.9832033 | L4: 1.3961689 | M4: -5.5870344 | N4: -3.6448674 | O4: 0.78027578 | P4: -2.8645917 | Q4: -0.044082472 | R4: -0.044082472 | S4: 0 | T4: -3.5755054 | U4: -0.18183904 | V4: -3.7573445 | W4: -0.26950067
A5: Adam Mokoka | B5: mokokad01 | C5: 2020 | D5: RS | E5: CHI | F5: 234 | G5: 112 | H5: 0.036498669 | I5: -0.92775824 | J5: -0.89125957 | K5: 11.022187 | L5: 3.6947023 | M5: 14.716889 | N5: 2.3840772 | O5: -0.036488013 | P5: 2.3475892 | Q5: 0.29123368 | R5: 0.29123368 | S5: 0 | T5: -0.077249094 | U5: -0.050402597 | V5: -0.12765169 | W5: -0.019182808
A6: Admiral Schofield | B6: schofad01 | C6: 2020 | D6: RS | E6: WAS | F6: 631 | G6: 293 | H6: -1.8293929 | I6: -3.8502692 | J6: -5.6796622 | K6: -2.3429117 | L6: -0.8182263 | M6: -3.161138 | N6: -2.0499134 | O6: -3.3514695 | P6: -5.4013829 | Q6: -0.39493468 | R6: -0.39493468 | S6: 0 | T6: -1.991493 | U6: -3.6974312 | V6: -5.6889243 | W6: -0.36452244
A7: Al Horford | B7: horfoal01 | C7: 2020 | D7: RS | E7: PHI | F7: 3860 | G7: 1848 | H7: -0.051061547 | I7: 0.75655409 | J7: 0.70549254 | K7: 2.0458919 | L7: 2.0731728 | M7: 4.1190647 | N7: 0.37747881 | O7: 1.0379959 | P7: 1.4154747 | Q7: 3.9113664 | R7: 3.9113664 | S7: 0 | T7: 1.0021553 | U7: 1.9614152 | V7: 2.9635705 | W7: -0.41672022
A8: Alec Burks | B8: burksal01 | C8: 2020 | D8: RS | E8: GSW | F8: 2960 | G8: 1390 | H8: 1.4936606 | I8: -1.3195754 | J8: 0.1740852 | K8: -3.4245491 | L8: 0.21436765 | M8: -3.2101815 | N8: 0.67084947 | O8: -1.0578756 | P8: -0.38702614 | Q8: 1.6750277 | R8: 1.6750277 | S8: 0 | T8: -0.25457953 | U8: -0.66695497 | V8: -0.9215345 | W8: -0.045116388
A9: Alec Burks | B9: burksal01 | C9: 2020 | D9: RS | E9: PHI | F9: 464 | G9: 222 | H9: 0.47216388 | I9: -0.23337525 | J9: 0.23878863 | K9: -4.3985146 | L9: -0.074017074 | M9: -4.4725317 | N9: -0.51724545 | O9: -0.24083923 | P9: -0.75808468 | Q9: 0.22488576 | R9: 0.22488576 | S9: 0 | T9: 0.61780526 | U9: -0.13679306 | V9: 0.4810122 | W9: -0.32873984
A10: Alen Smailagic | B10: smailal01 | C10: 2020 | D10: RS | E10: GSW | F10: 304 | G10: 139 | H10: -1.3281389 | I10: -1.0624497 | J10: -2.3905886 | K10: 3.4037013 | L10: -1.1502095 | M10: 2.2534918 | N10: -0.3341188 | O10: -1.0534756 | P10: -1.3875944 | Q10: 0.09734337 | R10: 0.09734337 | S10: 0 | T10: -0.74891417 | U10: -2.1076911 | V10: -2.8566053 | W10: 0.76470901
A11: Alex Caruso | B11: carusal01 | C11: 2020 | D11: RS | E11: LAL | F11: 2211 | G11: 1032 | H11: -0.89038944 | I11: 4.2449706 | J11: 3.3545812 | K11: -0.0089770458 | L11: 4.5785892 | M11: 4.5696121 | N11: -0.7937951 | O11: 4.4922961 | P11: 3.6985009 | Q11: 3.3993276 | R11: 3.3993276 | S11: 0 | T11: -0.55815418 | U11: 4.7092363 | V11: 4.1510822 | W11: 0.12078243
A12: Alex Len | B12: lenal01 | C12: 2020 | D12: RS | E12: ATL | F12: 1626 | G12: 745 | H12: -1.7228682 | I12: 1.7232455 | J12: 0.00037731712 | K12: -4.5906324 | L12: 0.50257284 | M12: -4.0880596 | N12: -2.3875462 | O12: 1.6425765 | P12: -0.74496975 | Q12: 0.75948762 | R12: 0.75948762 | S12: 0 | T12: -1.8288334 | U12: 0.76897143 | V12: -1.0598619 | W12: -0.35088189
A13: Alex Len | B13: lenal01 | C13: 2020 | D13: RS | E13: SAC | F13: 325 | G13: 150 | H13: -0.956369 | I13: 5.943051 | J13: 4.986682 | K13: -5.3287811 | L13: 9.342172 | M13: 4.0133909 | N13: -1.9287478 | O13: 7.0110627 | P13: 5.0823148 | Q13: 0.60205275 | R13: 0.60205275 | S13: 0 | T13: -2.4904333 | U13: 3.5986142 | V13: 1.1081809 | W13: 0.45009346
... A369: Malik Monk | B369: monkma01 | C369: 2020 | D369: RS | E369: CHA | F369: 2409 | G369: 1169 | H369: -1.0162905 | I369: -3.0351967 | J369: -4.0514873 | K369: -3.7187231 | L369: -1.7991956 | M369: -5.5179188 | N369: -1.5664838 | O369: -2.9338022 | P369: -4.500286 | Q369: -1.0473219 | R369: -1.0473219 | S369: 0 | T369: -1.384038 | U369: -4.0119799 | V369: -5.3960179 | W369: 0.33306383
A370: Malik Newman | B370: newmama01 | C370: 2020 | D370: RS | E370: CLE | F370: 8 | G370: 4 | N370: 0 | O370: 0 | P370: 0 | S370: 0 | T370: 0 | U370: 0 | V370: 0
A371: Marc Gasol | B371: gasolma01 | C371: 2020 | D371: RS | E371: TOR | F371: 2100 | G371: 990 | H371: -1.623194 | I371: 2.7126101 | J371: 1.089416 | K371: 1.0489708 | L371: 4.1221134 | M371: 5.1710842 | N371: -1.1791159 | O371: 3.0922299 | P371: 1.9131139 | Q371: 2.3499524 | R371: 2.3499524 | S371: 0 | T371: -1.236853 | U371: 3.0564706 | V371: 1.8196176 | W371: -0.23280028
A372: Marco Belinelli | B372: belinma01 | C372: 2020 | D372: RS | E372: SAS | F372: 1679 | G372: 779 | H372: -0.47095743 | I372: -3.89147 | J372: -4.3624275 | K372: 2.3342285 | L372: -0.24876255 | M372: 2.085466 | N372: 0.080402518 | O372: -3.3656519 | P372: -3.2852494 | Q372: -0.21192533 | R372: -0.21192533 | S372: 0 | T372: -0.19044986 | U372: -4.2005431 | V372: -4.3909929 | W372: -0.38697732
A373: Marcus Morris Sr. | B373: morrima03 | C373: 2020 | D373: RS | E373: NYK | F373: 2851 | G373: 1387 | H373: 1.6989033 | I373: -0.76962125 | J373: 0.92928208 | K373: 1.3825814 | L373: 0.19176991 | M373: 1.5743513 | N373: 1.8029234 | O373: -0.58438608 | P373: 1.2185373 | Q373: 2.7951854 | R373: 2.7951854 | S373: 0 | T373: 1.2847108 | U373: -0.75446195 | V373: 0.53024881 | W373: -0.47711362
A374: Marcus Morris Sr. | B374: morrima03 | C374: 2020 | D374: RS | E374: LAC | F374: 709 | G374: 340 | H374: -3.7427137 | I374: 1.2527192 | J374: -2.4899945 | K374: 3.3528336 | L374: 3.3576208 | M374: 6.7104544 | N374: -2.5377167 | O374: 1.7179798 | P374: -0.81973694 | Q374: 0.33501929 | R374: 0.33501929 | S374: 0 | T374: -1.1739681 | U374: 1.4617371 | V374: 0.28776898 | W374: 0.054944827
A375: Marcus Smart | B375: smartma01 | C375: 2020 | D375: RS | E375: BOS | F375: 3627 | G375: 1721 | H375: 1.4984266 | I375: 1.7689861 | J375: 3.2674127 | K375: -2.1775337 | L375: 2.8926432 | M375: 0.71510948 | N375: 0.79221681 | O375: 2.0739015 | P375: 2.8661184 | Q375: 4.9452659 | R375: 4.9452659 | S375: 0 | T375: 1.1814642 | U375: 2.673112 | V375: 3.8545762 | W375: 0.28970314
A376: Marial Shayok | B376: shayoma01 | C376: 2020 | D376: RS | E376: PHI | F376: 24 | G376: 10 | H376: -0.96719563 | I376: 0.34013336 | J376: -0.62706227 | K376: 4.3236008 | L376: -20.971005 | M376: -16.647404 | N376: 0.066949512 | O376: -4.1455168 | P376: -4.0785673 | Q376: -0.0068047849 | R376: -0.0068047849 | S376: 0 | T376: 2.0301138 | U376: -3.3786708 | V376: -1.348557 | W376: 0.39768219
A377: Mario Hezonja | B377: hezonma01 | C377: 2020 | D377: RS | E377: POR | F377: 1664 | G377: 767 | H377: -2.7127618 | I377: -1.0789564 | J377: -3.7917181 | K377: -5.4166325 | L377: -0.59233388 | M377: -6.0089663 | N377: -3.4474353 | O377: -0.99165186 | P377: -4.4390872 | Q377: -0.66221611 | R377: -0.66221611 | S377: 0 | T377: -2.9636748 | U377: -1.7636206 | V377: -4.7272954 | W377: 0.19080382
A378: Markelle Fultz | B378: fultzma01 | C378: 2020 | D378: RS | E378: ORL | F378: 3784 | G378: 1813 | H378: -1.3214216 | I378: -1.113312 | J378: -2.4347335 | K378: 3.0667636 | L378: -1.6208641 | M378: 1.4458994 | N378: -0.45611057 | O378: -1.3083856 | P378: -1.7644962 | Q378: 0.9080042 | R378: 0.9080042 | S378: 0 | T378: -0.77375783 | U378: -0.19140062 | V378: -0.96515845 | W378: -0.40042052
A379: Markieff Morris | B379: morrima02 | C379: 2020 | D379: RS | E379: DET | F379: 2066 | G379: 988 | H379: -1.376749 | I379: -2.6224966 | J379: -3.9992456 | K379: -0.6670339 | L379: -0.80610729 | M379: -1.4731412 | N379: -1.2917058 | O379: -2.3723837 | P379: -3.6640895 | Q379: -0.46256106 | R379: -0.46256106 | S379: 0 | T379: -1.1373555 | U379: -3.2330988 | V379: -4.3704543 | W379: 0.39592919
A380: Markieff Morris | B380: morrima02 | C380: 2020 | D380: RS | E380: LAL | F380: 263 | G380: 118 | H380: -0.73054302 | I380: -1.5481398 | J380: -2.2786829 | K380: -7.9881066 | L380: 4.5185929 | M380: -3.4695137 | N380: -2.3212936 | O380: -0.46550592 | P380: -2.7867995 | Q380: -0.0022322899 | R380: -0.0022322899 | S380: 0 | T380: -1.5800305 | U380: -0.36349795 | V380: -1.9435284 | W380: 0.77455421
A381: Marko Guduric | B381: gudurma01 | C381: 2020 | D381: RS | E381: MEM | F381: 1046 | G381: 476 | H381: -2.1380685 | I381: -2.3258127 | J381: -4.4638812 | K381: -1.5812288 | L381: -0.85960196 | M381: -2.4408308 | N381: -2.1226775 | O381: -2.1515463 | P381: -4.2742238 | Q381: -0.37141388 | R381: -0.37141388 | S381: 0 | T381: -2.1313087 | U381: -3.1023051 | V381: -5.2336138 | W381: 0.34385413
A382: Marques Bolden | B382: boldema01 | C382: 2020 | D382: RS | E382: CLE | F382: 7 | G382: 3 | H382: -2.6316388 | I382: 36.158382 | J382: 33.526743 | K382: -23.61755 | L382: 45.609246 | M382: 21.991696 | N382: -7.0630875 | O382: 40.858013 | P382: 33.794926 | Q382: 0.057670481 | R382: 0.057670481 | S382: 0 | T382: -6.1210793 | U382: 33.553419 | V382: 27.43234 | W382: 3.1626335
... A571: Zylan Cheatham | B571: cheatzy01 | C571: 2020 | D571: RS | E571: NOP | F571: 65 | G571: 31 | H571: -10.577804 | I571: -8.0666073 | J571: -18.644412 | K571: -19.740298 | L571: -8.3481324 | M571: -28.08843 | N571: -13.16926 | O571: -8.6053098 | P571: -21.77457 | Q571: -0.29785531 | R571: -0.29785531 | S571: 0 | T571: -13.079232 | U571: -8.6012111 | V571: -21.680443 | W571: -1.0306157

Sheet 2016 -PO
A1: player_name | B1: player_id | C1: season | D1: season_type | E1: team | F1: poss | G1: mp | H1: raptor_box_offense | I1: raptor_box_defense | J1: raptor_box_total | K1: raptor_onoff_offense | L1: raptor_onoff_defense | M1: raptor_onoff_total | N1: raptor_offense | O1: raptor_defense | P1: raptor_total | Q1: war_total
A2: {=_xlfn._xlws.FILTER(basketball_stats!A:Q, (basketball_stats!C:C=2016)*(basketball_stats!D:D="PO"))} -> Steven Adams | B2: adamsst01 | C2: 2016 | D2: PO | E2: OKC | F2: 1093 | G2: 553 | H2: 4.0293912 | I2: 1.1858461 | J2: 5.2152373 | K2: 2.1498733 | L2: -5.2967324 | M2: -3.1468591 | N2: 3.7125686 | O2: -0.11310966 | P2: 3.5994589 | Q2: 1.8120625
A3: Cole Aldrich | B3: aldrico01 | C3: 2016 | D3: PO | E3: LAC | F3: 158 | G3: 77 | H3: 0.55776353 | I3: 7.4985428 | J3: 8.0563063 | K3: 1.2824926 | L3: 0.89461828 | M3: 2.1771109 | N3: 0.86405923 | O3: 6.4942982 | P3: 7.3583574 | Q3: 0.40991049
A4: LaMarcus Aldridge | B4: aldrila01 | C4: 2016 | D4: PO | E4: SAS | F4: 654 | G4: 337 | H4: 2.8387264 | I4: 2.2286727 | J4: 5.0673991 | K4: -0.97461731 | L4: 2.7734751 | M4: 1.7988578 | N4: 2.0598076 | O4: 2.3731449 | P4: 4.4329525 | Q4: 1.2693406
A5: Lavoy Allen | B5: allenla01 | C5: 2016 | D5: PO | E5: IND | F5: 102 | G5: 51 | H5: -7.5405546 | I5: 2.0046581 | J5: -5.5358965 | K5: -18.267726 | L5: -0.46738502 | M5: -18.735111 | N5: -10.24062 | O5: 1.4807938 | P5: -8.7598261 | Q5: -0.16255689
A6: Tony Allen | B6: allento01 | C6: 2016 | D6: PO | E6: MEM | F6: 182 | G6: 94 | H6: -0.42232475 | I6: 2.6151102 | J6: 2.1927854 | K6: 0.31099027 | L6: 10.643365 | M6: 10.954355 | N6: -0.16600808 | O6: 4.5237422 | P6: 4.3577341 | Q6: 0.35811461
A7: Al-Farouq Aminu | B7: aminual01 | C7: 2016 | D7: PO | E7: POR | F7: 769 | G7: 372 | H7: 1.9395959 | I7: 4.5232805 | J7: 6.4628764 | K7: 1.9360332 | L7: 4.1826481 | M7: 6.1186813 | N7: 1.9830826 | O7: 4.7290399 | P7: 6.7121225 | Q7: 1.8766042
A8: Chris Andersen | B8: anderch01 | C8: 2016 | D8: PO | E8: MEM | F8: 149 | G8: 79 | H8: 0.073280424 | I8: -1.3822383 | J8: -1.3089579 | K8: -0.5098077 | L8: 4.6418523 | M8: 4.1320446 | N8: -0.10328213 | O8: -0.17000451 | P8: -0.27328664 | Q8: 0.10356113
A9: Justin Anderson | B9: anderju01 | C9: 2016 | D9: PO | E9: DAL | F9: 187 | G9: 95 | H9: 1.109342 | I9: 4.5541452 | J9: 5.6634871 | K9: 9.9175094 | L9: 3.3472122 | M9: 13.264722 | N9: 3.0499507 | O9: 4.6575037 | P9: 7.7074544 | Q9: 0.52768469
A10: Kyle Anderson | B10: anderky01 | C10: 2016 | D10: PO | E10: SAS | F10: 257 | G10: 129 | H10: -4.6166101 | I10: 1.1084454 | J10: -3.5081646 | K10: -8.5207173 | L10: -0.99474294 | M10: -9.5154603 | N10: -5.7214361 | O10: 0.61599043 | P10: -5.1054457 | Q10: -0.15829927
A11: Trevor Ariza | B11: arizatr01 | C11: 2016 | D11: PO | E11: HOU | F11: 378 | G11: 181 | H11: -5.4967935 | I11: 2.4359446 | J11: -3.060849 | K11: -12.272709 | L11: 1.7076664 | M11: -10.565043 | N11: -7.159061 | O11: 2.4100135 | P11: -4.7490475 | Q11: -0.19503968
A12: Leandro Barbosa | B12: barbole01 | C12: 2016 | D12: PO | E12: GSW | F12: 527 | G12: 254 | H12: 3.4415626 | I12: -2.1414811 | J12: 1.3000814 | K12: 1.8888815 | L12: 1.3099205 | M12: 3.198802 | N12: 3.2623459 | O12: -1.6352822 | P12: 1.6270637 | Q12: 0.58853202
A13: J.J. Barea | B13: bareajo01 | C13: 2016 | D13: PO | E13: DAL | F13: 196 | G13: 100 | H13: -6.0079614 | I13: -8.0551075 | J13: -14.063069 | K13: 10.804268 | L13: -14.474031 | M13: -3.6697636 | N13: -2.8393728 | O13: -9.8286165 | P13: -12.667989 | Q13: -0.52032603
A14: Harrison Barnes | B14: barneha02 | C14: 2016 | D14: PO | E14: GSW | F14: 1517 | G14: 743 | H14: -2.3226929 | I14: 0.17786029 | J14: -2.1448326 | K14: 0.12143638 | L14: -2.2528646 | M14: -2.1314282 | N14: -1.998203 | O14: -0.37889547 | P14: -2.3770985 | Q14: 0.14455526
... A216: Tyler Zeller | B216: zellety01 | C216: 2016 | D216: PO | E216: BOS | F216: 76 | G216: 38 | H216: 0.40644691 | I216: 4.5667285 | J216: 4.9731754 | K216: 10.58021 | L216: 4.2384203 | M216: 14.81863 | N216: 2.6858833 | O216: 4.8272363 | P216: 7.5131196 | Q216: 0.20697119

Sheet answers
A1: 1 | F1: 5
B2: predator_offense | C2: predator_defense | G2: raptor_offense | H2: raptor_defense | I2: war_reg_season
A3: mean | B3: =AVERAGE(basketball_stats!T:T) -> -1.0926224 | C3: =AVERAGE(basketball_stats!U:U) -> -0.68373976 | F3: James Harden | G3: =VLOOKUP("James Harden",basketball_stats!$A:$R,14, FALSE) -> 8.0437945 | H3: =VLOOKUP("James Harden",basketball_stats!$A:$R,15, FALSE) -> 1.9212007 | I3: =VLOOKUP("James Harden",basketball_stats!$A:$R,18, FALSE) -> 0
A4: median | B4: =MEDIAN(basketball_stats!T:T) -> -0.98350468 | C4: =MEDIAN(basketball_stats!U:U) -> -0.4619916 | F4: LeBron James | G4: =VLOOKUP($F4,basketball_stats!$A:$R,14, FALSE) -> 6.8899236 | H4: =VLOOKUP("LeBron James",basketball_stats!$A:$R,15, FALSE) -> 0.82354813 | I4: =VLOOKUP("LeBron James",basketball_stats!$A:$R,18, FALSE) -> 0
A5: min | B5: =MIN(basketball_stats!T:T) -> -42.027092 | C5: =MIN(basketball_stats!U:U) -> -48.886115 | F5: Giannis Antetokounmpo | G5: =VLOOKUP(F5,basketball_stats!$A:$R,14,FALSE) -> -1.1412139 | H5: =VLOOKUP(F5,basketball_stats!$A:$R,15, FALSE) -> 0.23340087 | I5: =VLOOKUP(F5,basketball_stats!$A:$R,18, FALSE) -> 1.784034
A6: max | B6: =MAX(basketball_stats!T:T) -> 42.890281 | C6: =MAX(basketball_stats!U:U) -> 42.989063 | F6: Kawhi Leonard | G6: =VLOOKUP(F6,basketball_stats!$A:$R,14, FALSE) -> 1.840325 | H6: =VLOOKUP(F6,basketball_stats!$A:$R,15, FALSE) -> 4.4031215 | I6: =VLOOKUP(F6,basketball_stats!$A:$R,18, FALSE) -> 0
F7: Rudy Gobert | G7: =VLOOKUP(F7,basketball_stats!$A:$R,14, FALSE) -> -4.1013613 | H7: =VLOOKUP(F7,basketball_stats!$A:$R,15, FALSE) -> 3.1599989 | I7: =VLOOKUP(F7,basketball_stats!$A:$R,18, FALSE) -> 0.40225768
A8: 2
B9: player_name | C9: season | D9: team | F9: best offensive player 2020 | G9: =_xlfn.CONCAT(F7, " , ",G7) -> Rudy Gobert , -4.101361323
A10: highest predator_offense | B10: =_xlfn.XLOOKUP(MAX(basketball_stats!T:T), basketball_stats!T:T, basketball_stats!A:A) -> DeAndre Liggins | C10: =_xlfn.XLOOKUP(MAX(basketball_stats!T:T), basketball_stats!T:T, basketball_stats!C:C) -> 2014 | D10: =_xlfn.XLOOKUP(MAX(basketball_stats!T:T), basketball_stats!T:T, basketball_stats!E:E) -> MIA | F10: best defensive player 2020 | G10: =_xlfn.CONCAT(F5," , ",H5) -> Giannis Antetokounmpo , 0.23340087
A11: highest predator_defense | B11: =_xlfn.XLOOKUP(MAX(basketball_stats!U:U), basketball_stats!U:U, basketball_stats!A:A) -> Tyler Davis | C11: =_xlfn.XLOOKUP(MAX(basketball_stats!U:U), basketball_stats!U:U, basketball_stats!C:C) -> 2019 | D11: =_xlfn.XLOOKUP(MAX(basketball_stats!U:U), basketball_stats!U:U, basketball_stats!E:E) -> OKC | F11: best regular season 2020 | G11: =_xlfn.CONCAT(F7, " , ",I7) -> Rudy Gobert , 0.402257682
H12: PHI | I12: DET
F13: 6a | G13: Detorit because their standard deviation is lower that PHI showing they are more consistent. | H13: =_xlfn.STDEV.P(War_Reg_Season_Pivot!B6:H6) -> 15.035193 | I13: =_xlfn.STDEV.P(War_Reg_Season_Pivot!B5:H5) -> 4.9884006
A14: 3 | F14: 6b | G14: After the 2018 Season | H14: =(War_Reg_Season_Pivot!Q6-War_Reg_Season_Pivot!P6)/War_Reg_Season_Pivot!Q6 -> -0.18130728
A15: sum war_total ATL | B15: =SUMIF(basketball_stats!E:E, "ATL", basketball_stats!Q:Q) -> 180.22131 | F15: 6c | G15: PHI was most consistent during the 2014–2016 timeframe, as performance values remained relatively stable
F16: 6d | G16: 2016-2018 showed the most growth
A18: 4
A19: first quartile | B19: =_xlfn.QUARTILE.INC('2016 -PO'!Q:Q, 1) -> -0.08253384
A20: second quartile | B20: =_xlfn.QUARTILE.INC('2016 -PO'!Q:Q, 2) -> 0.10650877
A21: third quartile | B21: =_xlfn.QUARTILE.INC('2016 -PO'!Q:Q, 3) -> 0.58248339
A22: player names | B22: {=_xlfn._xlws.FILTER('2016 -PO'!A:A,'2016 -PO'!Q:Q>=_xlfn.QUARTILE.INC('2016 -PO'!Q:Q,3))} -> player_name
B23: Steven Adams
B24: LaMarcus Aldridge
B25: Al-Farouq Aminu
B26: Leandro Barbosa
B27: Bismack Biyombo
B28: Andrew Bogut
B29: DeMarre Carroll
B30: Allen Crabbe
B31: Stephen Curry
B32: Luol Deng
B33: Goran Dragic
B34: Tim Duncan
... B76: Hassan Whiteside

Sheet formulas
A1: Cell | B1: Formula
A2: Q1
A3: B3 | B3: AVERAGE(basketball_stats!T:T)
A4: B4 | B4: MEDIAN(basketball_stats!T:T)
A5: B5 | B5: MIN(basketball_stats!T:T)
A6: B6 | B6: MAX(basketball_stats!T:T)
A7: C3 | B7: AVERAGE(basketball_stats!U:U)
A8: C4 | B8: MEDIAN(basketball_stats!U:U)
A9: C5 | B9: MIN(basketball_stats!U:U)
A10: C6 | B10: MAX(basketball_stats!U:U)
A11: Q2
A12: B10 | B12: XLOOKUP(MAX(basketball_stats!T:T), basketball_stats!T:T, basketball_stats!A:A)
A13: B11 | B13: XLOOKUP(MAX(basketball_stats!U:U), basketball_stats!U:U, basketball_stats!A:A)
A14: C10 | B14: XLOOKUP(MAX(basketball_stats!T:T), basketball_stats!T:T, basketball_stats!C:C)
A15: C11 | B15: XLOOKUP(MAX(basketball_stats!U:U), basketball_stats!U:U, basketball_stats!C:C)
A16: D10 | B16: XLOOKUP(MAX(basketball_stats!T:T), basketball_stats!T:T, basketball_stats!E:E)
A17: D11 | B17: XLOOKUP(MAX(basketball_stats!U:U), basketball_stats!U:U, basketball_stats!E:E)
A18: Q3
A19: B15 | B19: SUMIF(basketball_stats!E:E, "ATL", basketball_stats!Q:Q)
A20: Q4
A21: b.
A22: B19 | B22: QUARTILE.INC('2016 -PO'!Q:Q, 1)
A23: B20 | B23: QUARTILE.INC('2016 -PO'!Q:Q, 2)
A24: B21 | B24: QUARTILE.INC('2016 -PO'!Q:Q, 3)
A25: B22 | B25: FILTER('2016 -PO'!A:A,'2016 -PO'!Q:Q>=QUARTILE.INC('2016 -PO'!Q:Q,3))
A26: Q5
A27: G3 | B27: VLOOKUP(F3,basketball_stats!$A:$R,14, FALSE)
A28: G4 | B28: VLOOKUP(F4,basketball_stats!$A:$R,14, FALSE)
A29: G5 | B29: VLOOKUP(F5,basketball_stats!$A:$R,14, FALSE)
A30: G6 | B30: VLOOKUP(F6,basketball_stats!$A:$R,14, FALSE)
A31: G7 | B31: VLOOKUP(F7,basketball_stats!$A:$R,14, FALSE)
A32: H3 | B32: VLOOKUP(F3,basketball_stats!$A:$R,15, FALSE)
A33: H4 | B33: VLOOKUP(F4,basketball_stats!$A:$R,15, FALSE)
A34: H5 | B34: VLOOKUP(F5,basketball_stats!$A:$R,15, FALSE)
A35: H6 | B35: VLOOKUP(F6,basketball_stats!$A:$R,15, FALSE)
B36: VLOOKUP(F7,basketball_stats!$A:$R,15, FALSE)
A37: I3 | B37: VLOOKUP(F3,basketball_stats!$A:$R,18, FALSE)
A38: I4 | B38: VLOOKUP(F4,basketball_stats!$A:$R,18, FALSE)
A39: I5 | B39: VLOOKUP(F5,basketball_stats!$A:$R,18, FALSE)
A40: I6 | B40: VLOOKUP(F6,basketball_stats!$A:$R,18, FALSE)
...

Sheet data_dictionary
A1: player_name | B1: Player name
A2: player_id | B2: Basketball-Reference.com player ID
A3: season | B3: Season
A4: season_type | B4: Regular season (RS) or playoff (PO)
A5: team | B5: Basketball-Reference ID of team
A6: poss | B6: Possessions played
A7: mp | B7: Minutes played
A8: raptor_box_offense | B8: Points above average per 100 possessions added by player on offense, based only on box score estimate
A9: raptor_box_defense | B9: Points above average per 100 possessions added by player on defense, based only on box score estimate
A10: raptor_box_total | B10: Points above average per 100 possessions added by player, based only on box score estimate
A11: raptor_onoff_offense | B11: Points above average per 100 possessions added by player on offense, based only on plus-minus data
A12: raptor_onoff_defense | B12: Points above average per 100 possessions added by player on defense, based only on plus-minus data
... A23: pace_impact | B23: Player impact on team possessions per 48 minutes
